<sdf version='1.6'>
  <world name='default'>
    <light name='sun' type='directional'>
      <cast_shadows>1</cast_shadows>
      <pose frame=''>0 0 10 0 -0 0</pose>
      <diffuse>0.8 0.8 0.8 1</diffuse>
      <specular>0.2 0.2 0.2 1</specular>
      <attenuation>
        <range>1000</range>
        <constant>0.9</constant>
        <linear>0.01</linear>
        <quadratic>0.001</quadratic>
      </attenuation>
      <direction>-0.5 0.1 -0.9</direction>
    </light>
    <gravity>0 0 -9.8</gravity>
    <magnetic_field>6e-06 2.3e-05 -4.2e-05</magnetic_field>
    <atmosphere type='adiabatic'/>
    <physics name='default_physics' default='0' type='ode'>
      <max_step_size>0.001</max_step_size>
      <real_time_factor>1</real_time_factor>
      <real_time_update_rate>1000</real_time_update_rate>
    </physics>
    <scene>
      <ambient>0.4 0.4 0.4 1</ambient>
      <background>0.7 0.7 0.7 1</background>
      <shadows>1</shadows>
    </scene>
    <audio>
      <device>default</device>
    </audio>
    <wind/>
    <spherical_coordinates>
      <surface_model>EARTH_WGS84</surface_model>
      <latitude_deg>0</latitude_deg>
      <longitude_deg>0</longitude_deg>
      <elevation>0</elevation>
      <heading_deg>0</heading_deg>
    </spherical_coordinates>
    <model name='forest_ground'>
      <link name='link_0'>
        <inertial>
          <mass>1</mass>
          <inertia>
            <ixx>0.166667</ixx>
            <ixy>0</ixy>
            <ixz>0</ixz>
            <iyy>0.166667</iyy>
            <iyz>0</iyz>
            <izz>0.166667</izz>
          </inertia>
        </inertial>
        <pose frame=''>3e-06 -2e-06 0 0.216292 0.022741 0.004996</pose>
        <visual name='visual'>
          <pose frame=''>0 0 0 0 -0 0</pose>
          <geometry>
            <mesh>
              <uri>/root/catkin_ws/src/soma_pkg/soma_description/meshes/forest4.dae</uri>
              <scale>1 1 1</scale>
            </mesh>
          </geometry>
          <material>
            <lighting>1</lighting>
            <script>
              <uri>file://media/materials/scripts/gazebo.material</uri>
              <name>Gazebo/Grey</name>
            </script>
          </material>
          <transparency>0</transparency>
          <cast_shadows>1</cast_shadows>
        </visual>
        <collision name='collision'>
          <laser_retro>0</laser_retro>
          <max_contacts>10</max_contacts>
          <pose frame=''>0 0 0 0 -0 0</pose>
          <geometry>
            <mesh>
              <uri>/root/catkin_ws/src/soma_pkg/soma_description/meshes/forest4.dae</uri>
              <scale>1 1 1</scale>
            </mesh>
          </geometry>
          <surface>
            <friction>
              <ode>
                <mu>inf</mu>
                <mu2>inf</mu2>
                <fdir1>0 0 0</fdir1>
                <slip1>0</slip1>
                <slip2>0</slip2>
              </ode>
              <torsional>
                <coefficient>1</coefficient>
                <patch_radius>0</patch_radius>
                <surface_radius>0</surface_radius>
                <use_patch_radius>1</use_patch_radius>
                <ode>
                  <slip>0</slip>
                </ode>
              </torsional>
            </friction>
            <bounce>
              <restitution_coefficient>0</restitution_coefficient>
              <threshold>1e+100</threshold>
            </bounce>
            <contact>
              <collide_without_contact>0</collide_without_contact>
              <collide_without_contact_bitmask>1</collide_without_contact_bitmask>
              <collide_bitmask>1</collide_bitmask>
              <ode>
                <soft_cfm>0</soft_cfm>
                <soft_erp>0.2</soft_erp>
                <kp>1e+07</kp>
                <kd>1</kd>
                <max_vel>0.01</max_vel>
                <min_depth>0</min_depth>
              </ode>
              <bullet>
                <split_impulse>1</split_impulse>
                <split_impulse_penetration_threshold>-0.01</split_impulse_penetration_threshold>
                <soft_cfm>0</soft_cfm>
                <soft_erp>0.2</soft_erp>
                <kp>1e+13</kp>
                <kd>1</kd>
              </bullet>
            </contact>
          </surface>
        </collision>
        <self_collide>0</self_collide>
        <enable_wind>0</enable_wind>
        <kinematic>0</kinematic>
      </link>
      <static>1</static>
      <allow_auto_disable>1</allow_auto_disable>
      <pose frame=''>-2.49043 -1.66733 0 0 -0 0</pose>
    </model>
    <model name='pine_tree'>
      <static>1</static>
      <link name='link'>
        <collision name='collision'>
          <geometry>
            <mesh>
              <uri>model://pine_tree/meshes/pine_tree.dae</uri>
            </mesh>
          </geometry>
          <max_contacts>10</max_contacts>
          <surface>
            <contact>
              <ode/>
            </contact>
            <bounce/>
            <friction>
              <torsional>
                <ode/>
              </torsional>
              <ode/>
            </friction>
          </surface>
        </collision>
        <visual name='branch'>
          <geometry>
            <mesh>
              <uri>model://pine_tree/meshes/pine_tree.dae</uri>
              <submesh>
                <name>Branch</name>
              </submesh>
            </mesh>
          </geometry>
          <material>
            <script>
              <uri>model://pine_tree/materials/scripts/</uri>
              <uri>model://pine_tree/materials/textures/</uri>
              <name>PineTree/Branch</name>
            </script>
          </material>
        </visual>
        <visual name='bark'>
          <geometry>
            <mesh>
              <uri>model://pine_tree/meshes/pine_tree.dae</uri>
              <submesh>
                <name>Bark</name>
              </submesh>
            </mesh>
          </geometry>
          <material>
            <script>
              <uri>model://pine_tree/materials/scripts/</uri>
              <uri>model://pine_tree/materials/textures/</uri>
              <name>PineTree/Bark</name>
            </script>
          </material>
        </visual>
        <self_collide>0</self_collide>
        <enable_wind>0</enable_wind>
        <kinematic>0</kinematic>
      </link>
      <pose frame=''>-6.82818 7.49526 0 0 -0 0</pose>
    </model>
    <model name='pine_tree_clone'>
      <static>1</static>
      <link name='link'>
        <collision name='collision'>
          <geometry>
            <mesh>
              <uri>model://pine_tree/meshes/pine_tree.dae</uri>
            </mesh>
          </geometry>
          <max_contacts>10</max_contacts>
          <surface>
            <contact>
              <ode/>
            </contact>
            <bounce/>
            <friction>
              <torsional>
                <ode/>
              </torsional>
              <ode/>
            </friction>
          </surface>
        </collision>
        <visual name='branch'>
          <geometry>
            <mesh>
              <uri>model://pine_tree/meshes/pine_tree.dae</uri>
              <submesh>
                <name>Branch</name>
              </submesh>
            </mesh>
          </geometry>
          <material>
            <script>
              <uri>model://pine_tree/materials/scripts/</uri>
              <uri>model://pine_tree/materials/textures/</uri>
              <name>PineTree/Branch</name>
            </script>
          </material>
        </visual>
        <visual name='bark'>
          <geometry>
            <mesh>
              <uri>model://pine_tree/meshes/pine_tree.dae</uri>
              <submesh>
                <name>Bark</name>
              </submesh>
            </mesh>
          </geometry>
          <material>
            <script>
              <uri>model://pine_tree/materials/scripts/</uri>
              <uri>model://pine_tree/materials/textures/</uri>
              <name>PineTree/Bark</name>
            </script>
          </material>
        </visual>
        <self_collide>0</self_collide>
        <enable_wind>0</enable_wind>
        <kinematic>0</kinematic>
      </link>
      <pose frame=''>-3.83295 4.24801 1.53551 0 -0 0</pose>
    </model>
    <model name='pine_tree_clone_0'>
      <static>1</static>
      <link name='link'>
        <collision name='collision'>
          <geometry>
            <mesh>
              <uri>model://pine_tree/meshes/pine_tree.dae</uri>
            </mesh>
          </geometry>
          <max_contacts>10</max_contacts>
          <surface>
            <contact>
              <ode/>
            </contact>
            <bounce/>
            <friction>
              <torsional>
                <ode/>
              </torsional>
              <ode/>
            </friction>
          </surface>
        </collision>
        <visual name='branch'>
          <geometry>
            <mesh>
              <uri>model://pine_tree/meshes/pine_tree.dae</uri>
              <submesh>
                <name>Branch</name>
              </submesh>
            </mesh>
          </geometry>
          <material>
            <script>
              <uri>model://pine_tree/materials/scripts/</uri>
              <uri>model://pine_tree/materials/textures/</uri>
              <name>PineTree/Branch</name>
            </script>
          </material>
        </visual>
        <visual name='bark'>
          <geometry>
            <mesh>
              <uri>model://pine_tree/meshes/pine_tree.dae</uri>
              <submesh>
                <name>Bark</name>
              </submesh>
            </mesh>
          </geometry>
          <material>
            <script>
              <uri>model://pine_tree/materials/scripts/</uri>
              <uri>model://pine_tree/materials/textures/</uri>
              <name>PineTree/Bark</name>
            </script>
          </material>
        </visual>
        <self_collide>0</self_collide>
        <enable_wind>0</enable_wind>
        <kinematic>0</kinematic>
      </link>
      <pose frame=''>-7.54728 -1.52029 1.53551 0 -0 0</pose>
    </model>
    <model name='pine_tree_clone_1'>
      <static>1</static>
      <link name='link'>
        <collision name='collision'>
          <geometry>
            <mesh>
              <uri>model://pine_tree/meshes/pine_tree.dae</uri>
            </mesh>
          </geometry>
          <max_contacts>10</max_contacts>
          <surface>
            <contact>
              <ode/>
            </contact>
            <bounce/>
            <friction>
              <torsional>
                <ode/>
              </torsional>
              <ode/>
            </friction>
          </surface>
        </collision>
        <visual name='branch'>
          <geometry>
            <mesh>
              <uri>model://pine_tree/meshes/pine_tree.dae</uri>
              <submesh>
                <name>Branch</name>
              </submesh>
            </mesh>
          </geometry>
          <material>
            <script>
              <uri>model://pine_tree/materials/scripts/</uri>
              <uri>model://pine_tree/materials/textures/</uri>
              <name>PineTree/Branch</name>
            </script>
          </material>
        </visual>
        <visual name='bark'>
          <geometry>
            <mesh>
              <uri>model://pine_tree/meshes/pine_tree.dae</uri>
              <submesh>
                <name>Bark</name>
              </submesh>
            </mesh>
          </geometry>
          <material>
            <script>
              <uri>model://pine_tree/materials/scripts/</uri>
              <uri>model://pine_tree/materials/textures/</uri>
              <name>PineTree/Bark</name>
            </script>
          </material>
        </visual>
        <self_collide>0</self_collide>
        <enable_wind>0</enable_wind>
        <kinematic>0</kinematic>
      </link>
      <pose frame=''>-3.6966 -6.06668 1.53551 0 -0 0</pose>
    </model>
    <model name='pine_tree_clone_2'>
      <static>1</static>
      <link name='link'>
        <collision name='collision'>
          <geometry>
            <mesh>
              <uri>model://pine_tree/meshes/pine_tree.dae</uri>
            </mesh>
          </geometry>
          <max_contacts>10</max_contacts>
          <surface>
            <contact>
              <ode/>
            </contact>
            <bounce/>
            <friction>
              <torsional>
                <ode/>
              </torsional>
              <ode/>
            </friction>
          </surface>
        </collision>
        <visual name='branch'>
          <geometry>
            <mesh>
              <uri>model://pine_tree/meshes/pine_tree.dae</uri>
              <submesh>
                <name>Branch</name>
              </submesh>
            </mesh>
          </geometry>
          <material>
            <script>
              <uri>model://pine_tree/materials/scripts/</uri>
              <uri>model://pine_tree/materials/textures/</uri>
              <name>PineTree/Branch</name>
            </script>
          </material>
        </visual>
        <visual name='bark'>
          <geometry>
            <mesh>
              <uri>model://pine_tree/meshes/pine_tree.dae</uri>
              <submesh>
                <name>Bark</name>
              </submesh>
            </mesh>
          </geometry>
          <material>
            <script>
              <uri>model://pine_tree/materials/scripts/</uri>
              <uri>model://pine_tree/materials/textures/</uri>
              <name>PineTree/Bark</name>
            </script>
          </material>
        </visual>
        <self_collide>0</self_collide>
        <enable_wind>0</enable_wind>
        <kinematic>0</kinematic>
      </link>
      <pose frame=''>2.3771 7.80667 1.43203 0 -0 0</pose>
    </model>
    <model name='pine_tree_clone_3'>
      <static>1</static>
      <link name='link'>
        <collision name='collision'>
          <geometry>
            <mesh>
              <uri>model://pine_tree/meshes/pine_tree.dae</uri>
            </mesh>
          </geometry>
          <max_contacts>10</max_contacts>
          <surface>
            <contact>
              <ode/>
            </contact>
            <bounce/>
            <friction>
              <torsional>
                <ode/>
              </torsional>
              <ode/>
            </friction>
          </surface>
        </collision>
        <visual name='branch'>
          <geometry>
            <mesh>
              <uri>model://pine_tree/meshes/pine_tree.dae</uri>
              <submesh>
                <name>Branch</name>
              </submesh>
            </mesh>
          </geometry>
          <material>
            <script>
              <uri>model://pine_tree/materials/scripts/</uri>
              <uri>model://pine_tree/materials/textures/</uri>
              <name>PineTree/Branch</name>
            </script>
          </material>
        </visual>
        <visual name='bark'>
          <geometry>
            <mesh>
              <uri>model://pine_tree/meshes/pine_tree.dae</uri>
              <submesh>
                <name>Bark</name>
              </submesh>
            </mesh>
          </geometry>
          <material>
            <script>
              <uri>model://pine_tree/materials/scripts/</uri>
              <uri>model://pine_tree/materials/textures/</uri>
              <name>PineTree/Bark</name>
            </script>
          </material>
        </visual>
        <self_collide>0</self_collide>
        <enable_wind>0</enable_wind>
        <kinematic>0</kinematic>
      </link>
      <pose frame=''>2.04285 2.46971 1.43203 0 -0 0</pose>
    </model>
    <model name='pine_tree_clone_4'>
      <static>1</static>
      <link name='link'>
        <collision name='collision'>
          <geometry>
            <mesh>
              <uri>model://pine_tree/meshes/pine_tree.dae</uri>
            </mesh>
          </geometry>
          <max_contacts>10</max_contacts>
          <surface>
            <contact>
              <ode/>
            </contact>
            <bounce/>
            <friction>
              <torsional>
                <ode/>
              </torsional>
              <ode/>
            </friction>
          </surface>
        </collision>
        <visual name='branch'>
          <geometry>
            <mesh>
              <uri>model://pine_tree/meshes/pine_tree.dae</uri>
              <submesh>
                <name>Branch</name>
              </submesh>
            </mesh>
          </geometry>
          <material>
            <script>
              <uri>model://pine_tree/materials/scripts/</uri>
              <uri>model://pine_tree/materials/textures/</uri>
              <name>PineTree/Branch</name>
            </script>
          </material>
        </visual>
        <visual name='bark'>
          <geometry>
            <mesh>
              <uri>model://pine_tree/meshes/pine_tree.dae</uri>
              <submesh>
                <name>Bark</name>
              </submesh>
            </mesh>
          </geometry>
          <material>
            <script>
              <uri>model://pine_tree/materials/scripts/</uri>
              <uri>model://pine_tree/materials/textures/</uri>
              <name>PineTree/Bark</name>
            </script>
          </material>
        </visual>
        <self_collide>0</self_collide>
        <enable_wind>0</enable_wind>
        <kinematic>0</kinematic>
      </link>
      <pose frame=''>-0.452947 -3.458 1.43203 0 -0 0</pose>
    </model>
    <model name='pine_tree_clone_5'>
      <static>1</static>
      <link name='link'>
        <collision name='collision'>
          <geometry>
            <mesh>
              <uri>model://pine_tree/meshes/pine_tree.dae</uri>
            </mesh>
          </geometry>
          <max_contacts>10</max_contacts>
          <surface>
            <contact>
              <ode/>
            </contact>
            <bounce/>
            <friction>
              <torsional>
                <ode/>
              </torsional>
              <ode/>
            </friction>
          </surface>
        </collision>
        <visual name='branch'>
          <geometry>
            <mesh>
              <uri>model://pine_tree/meshes/pine_tree.dae</uri>
              <submesh>
                <name>Branch</name>
              </submesh>
            </mesh>
          </geometry>
          <material>
            <script>
              <uri>model://pine_tree/materials/scripts/</uri>
              <uri>model://pine_tree/materials/textures/</uri>
              <name>PineTree/Branch</name>
            </script>
          </material>
        </visual>
        <visual name='bark'>
          <geometry>
            <mesh>
              <uri>model://pine_tree/meshes/pine_tree.dae</uri>
              <submesh>
                <name>Bark</name>
              </submesh>
            </mesh>
          </geometry>
          <material>
            <script>
              <uri>model://pine_tree/materials/scripts/</uri>
              <uri>model://pine_tree/materials/textures/</uri>
              <name>PineTree/Bark</name>
            </script>
          </material>
        </visual>
        <self_collide>0</self_collide>
        <enable_wind>0</enable_wind>
        <kinematic>0</kinematic>
      </link>
      <pose frame=''>9.22665 3.50513 1.43203 0 -0 0</pose>
    </model>
    <model name='pine_tree_clone_6'>
      <static>1</static>
      <link name='link'>
        <collision name='collision'>
          <geometry>
            <mesh>
              <uri>model://pine_tree/meshes/pine_tree.dae</uri>
            </mesh>
          </geometry>
          <max_contacts>10</max_contacts>
          <surface>
            <contact>
              <ode/>
            </contact>
            <bounce/>
            <friction>
              <torsional>
                <ode/>
              </torsional>
              <ode/>
            </friction>
          </surface>
        </collision>
        <visual name='branch'>
          <geometry>
            <mesh>
              <uri>model://pine_tree/meshes/pine_tree.dae</uri>
              <submesh>
                <name>Branch</name>
              </submesh>
            </mesh>
          </geometry>
          <material>
            <script>
              <uri>model://pine_tree/materials/scripts/</uri>
              <uri>model://pine_tree/materials/textures/</uri>
              <name>PineTree/Branch</name>
            </script>
          </material>
        </visual>
        <visual name='bark'>
          <geometry>
            <mesh>
              <uri>model://pine_tree/meshes/pine_tree.dae</uri>
              <submesh>
                <name>Bark</name>
              </submesh>
            </mesh>
          </geometry>
          <material>
            <script>
              <uri>model://pine_tree/materials/scripts/</uri>
              <uri>model://pine_tree/materials/textures/</uri>
              <name>PineTree/Bark</name>
            </script>
          </material>
        </visual>
        <self_collide>0</self_collide>
        <enable_wind>0</enable_wind>
        <kinematic>0</kinematic>
      </link>
      <pose frame=''>8.79848 -0.684913 1.43203 0 -0 0</pose>
    </model>
    <model name='pine_tree_clone_7'>
      <static>1</static>
      <link name='link'>
        <collision name='collision'>
          <geometry>
            <mesh>
              <uri>model://pine_tree/meshes/pine_tree.dae</uri>
            </mesh>
          </geometry>
          <max_contacts>10</max_contacts>
          <surface>
            <contact>
              <ode/>
            </contact>
            <bounce/>
            <friction>
              <torsional>
                <ode/>
              </torsional>
              <ode/>
            </friction>
          </surface>
        </collision>
        <visual name='branch'>
          <geometry>
            <mesh>
              <uri>model://pine_tree/meshes/pine_tree.dae</uri>
              <submesh>
                <name>Branch</name>
              </submesh>
            </mesh>
          </geometry>
          <material>
            <script>
              <uri>model://pine_tree/materials/scripts/</uri>
              <uri>model://pine_tree/materials/textures/</uri>
              <name>PineTree/Branch</name>
            </script>
          </material>
        </visual>
        <visual name='bark'>
          <geometry>
            <mesh>
              <uri>model://pine_tree/meshes/pine_tree.dae</uri>
              <submesh>
                <name>Bark</name>
              </submesh>
            </mesh>
          </geometry>
          <material>
            <script>
              <uri>model://pine_tree/materials/scripts/</uri>
              <uri>model://pine_tree/materials/textures/</uri>
              <name>PineTree/Bark</name>
            </script>
          </material>
        </visual>
        <self_collide>0</self_collide>
        <enable_wind>0</enable_wind>
        <kinematic>0</kinematic>
      </link>
      <pose frame=''>4.75789 -6.91299 1.43203 0 -0 0</pose>
    </model>
    <state world_name='default'>
      <sim_time>637 685000000</sim_time>
      <real_time>0 0</real_time>
      <wall_time>1634718228 335269500</wall_time>
      <iterations>0</iterations>
      <model name='forest_ground'>
        <pose frame=''>0.066802 0.804489 0.09374 -0.21706 -0.027407 -0.002531</pose>
        <scale>1 1 1</scale>
        <link name='link_0'>
          <pose frame=''>0.066805 0.804487 0.093741 -0.000825 -0.004124 -0.002551</pose>
          <velocity>0 0 0 0 -0 0</velocity>
          <acceleration>0 0 0 0 -0 0</acceleration>
          <wrench>0 0 0 0 -0 0</wrench>
        </link>
      </model>
      <model name='pine_tree'>
        <pose frame=''>-6.82818 7.49526 0.153672 0 -0 0</pose>
        <scale>1 1 1</scale>
        <link name='link'>
          <pose frame=''>-6.82818 7.49526 0.153672 0 -0 0</pose>
          <velocity>0 0 0 0 -0 0</velocity>
          <acceleration>0 0 0 0 -0 0</acceleration>
          <wrench>0 0 0 0 -0 0</wrench>
        </link>
      </model>
      <model name='pine_tree_clone'>
        <pose frame=''>-3.83295 4.24801 0.158308 0 -0 0</pose>
        <scale>1 1 1</scale>
        <link name='link'>
          <pose frame=''>-3.83295 4.24801 0.158308 0 -0 0</pose>
          <velocity>0 0 0 0 -0 0</velocity>
          <acceleration>0 0 0 0 -0 0</acceleration>
          <wrench>0 0 0 0 -0 0</wrench>
        </link>
      </model>
      <model name='pine_tree_clone_0'>
        <pose frame=''>-7.54728 -1.52029 0.185956 0 -0 0</pose>
        <scale>1 1 1</scale>
        <link name='link'>
          <pose frame=''>-7.54728 -1.52029 0.185956 0 -0 0</pose>
          <velocity>0 0 0 0 -0 0</velocity>
          <acceleration>0 0 0 0 -0 0</acceleration>
          <wrench>0 0 0 0 -0 0</wrench>
        </link>
      </model>
      <model name='pine_tree_clone_1'>
        <pose frame=''>-3.6966 -6.06668 0.182748 0 0 -0.270978</pose>
        <scale>1 1 1</scale>
        <link name='link'>
          <pose frame=''>-3.6966 -6.06668 0.182748 0 0 -0.270978</pose>
          <velocity>0 0 0 0 -0 0</velocity>
          <acceleration>0 0 0 0 -0 0</acceleration>
          <wrench>0 0 0 0 -0 0</wrench>
        </link>
      </model>
      <model name='pine_tree_clone_2'>
        <pose frame=''>2.3771 7.80667 0.205653 0 -0 0</pose>
        <scale>1 1 1</scale>
        <link name='link'>
          <pose frame=''>2.3771 7.80667 0.205653 0 -0 0</pose>
          <velocity>0 0 0 0 -0 0</velocity>
          <acceleration>0 0 0 0 -0 0</acceleration>
          <wrench>0 0 0 0 -0 0</wrench>
        </link>
      </model>
      <model name='pine_tree_clone_3'>
        <pose frame=''>2.51408 2.59422 0.252949 0 -0 0</pose>
        <scale>1 1 1</scale>
        <link name='link'>
          <pose frame=''>2.51408 2.59422 0.252949 0 -0 0</pose>
          <velocity>0 0 0 0 -0 0</velocity>
          <acceleration>0 0 0 0 -0 0</acceleration>
          <wrench>0 0 0 0 -0 0</wrench>
        </link>
      </model>
      <model name='pine_tree_clone_4'>
        <pose frame=''>-0.452947 -3.458 0.239143 0 -0 0</pose>
        <scale>1 1 1</scale>
        <link name='link'>
          <pose frame=''>-0.452947 -3.458 0.239143 0 -0 0</pose>
          <velocity>0 0 0 0 -0 0</velocity>
          <acceleration>0 0 0 0 -0 0</acceleration>
          <wrench>0 0 0 0 -0 0</wrench>
        </link>
      </model>
      <model name='pine_tree_clone_5'>
        <pose frame=''>9.22665 3.50513 0.393493 0 -0 0</pose>
        <scale>1 1 1</scale>
        <link name='link'>
          <pose frame=''>9.22665 3.50513 0.393493 0 -0 0</pose>
          <velocity>0 0 0 0 -0 0</velocity>
          <acceleration>0 0 0 0 -0 0</acceleration>
          <wrench>0 0 0 0 -0 0</wrench>
        </link>
      </model>
      <model name='pine_tree_clone_6'>
        <pose frame=''>8.54039 -0.806175 0.273568 0 -0 0</pose>
        <scale>1 1 1</scale>
        <link name='link'>
          <pose frame=''>8.54039 -0.806175 0.273568 0 -0 0</pose>
          <velocity>0 0 0 0 -0 0</velocity>
          <acceleration>0 0 0 0 -0 0</acceleration>
          <wrench>0 0 0 0 -0 0</wrench>
        </link>
      </model>
      <model name='pine_tree_clone_7'>
        <pose frame=''>4.75789 -6.91299 0.170268 0 -0 0</pose>
        <scale>1 1 1</scale>
        <link name='link'>
          <pose frame=''>4.75789 -6.91299 0.170268 0 -0 0</pose>
          <velocity>0 0 0 0 -0 0</velocity>
          <acceleration>0 0 0 0 -0 0</acceleration>
          <wrench>0 0 0 0 -0 0</wrench>
        </link>
      </model>
      <model name='soma'>
        <pose frame=''>0 0 0.2 0 -0 0</pose>
        <scale>1 1 1</scale>
        <link name='ackermann_front_steer'>
          <pose frame=''>0.525 0 0.4286 0 -0 0</pose>
          <velocity>0 0 0 0 -0 0</velocity>
          <acceleration>0 0 0 0 -0 0</acceleration>
          <wrench>0 0 0 0 -0 0</wrench>
        </link>
        <link name='ackermann_virtual_rear_wheel'>
          <pose frame=''>-0.525 0 0.4286 -1.5708 0 0</pose>
          <velocity>0 0 0 0 -0 0</velocity>
          <acceleration>0 0 0 0 -0 0</acceleration>
          <wrench>0 0 0 0 -0 0</wrench>
        </link>
        <link name='base_link'>
          <pose frame=''>0 0 0.2 0 -0 0</pose>
          <velocity>0 0 0 0 -0 0</velocity>
          <acceleration>0 0 0 0 -0 0</acceleration>
          <wrench>0 0 0 0 -0 0</wrench>
        </link>
        <link name='left_front_wheel'>
          <pose frame=''>0.525 0.4389 0.4286 -1.5708 0 0</pose>
          <velocity>0 0 0 0 -0 0</velocity>
          <acceleration>0 0 0 0 -0 0</acceleration>
          <wrench>0 0 0 0 -0 0</wrench>
        </link>
        <link name='left_front_wheel_assembly'>
          <pose frame=''>0.525 0.4389 0.4286 0 -0 0</pose>
          <velocity>0 0 0 0 -0 0</velocity>
          <acceleration>0 0 0 0 -0 0</acceleration>
          <wrench>0 0 0 0 -0 0</wrench>
        </link>
        <link name='left_rear_wheel'>
          <pose frame=''>-0.525 0.4389 0.4286 -1.5708 0 0</pose>
          <velocity>0 0 0 0 -0 0</velocity>
          <acceleration>0 0 0 0 -0 0</acceleration>
          <wrench>0 0 0 0 -0 0</wrench>
        </link>
        <link name='right_front_wheel'>
          <pose frame=''>0.525 -0.4389 0.4286 -1.5708 0 0</pose>
          <velocity>0 0 0 0 -0 0</velocity>
          <acceleration>0 0 0 0 -0 0</acceleration>
          <wrench>0 0 0 0 -0 0</wrench>
        </link>
        <link name='right_front_wheel_assembly'>
          <pose frame=''>0.525 -0.4389 0.4286 0 -0 0</pose>
          <velocity>0 0 0 0 -0 0</velocity>
          <acceleration>0 0 0 0 -0 0</acceleration>
          <wrench>0 0 0 0 -0 0</wrench>
        </link>
        <link name='right_rear_wheel'>
          <pose frame=''>-0.525 -0.4389 0.4286 -1.5708 0 0</pose>
          <velocity>0 0 0 0 -0 0</velocity>
          <acceleration>0 0 0 0 -0 0</acceleration>
          <wrench>0 0 0 0 -0 0</wrench>
        </link>
      </model>
      <light name='sun'>
        <pose frame=''>0 0 10 0 -0 0</pose>
      </light>
    </state>
    <gui fullscreen='0'>
      <camera name='user_camera'>
        <pose frame=''>0.492279 -12.6752 27.6961 0 1.116 1.52959</pose>
        <view_controller>orbit</view_controller>
        <projection_type>perspective</projection_type>
      </camera>
    </gui>
    <model name='soma'>
      <link name='base_link'>
        <pose frame=''>0 0 0 0 -0 0</pose>
        <inertial>
          <pose frame=''>-0.018176 0 0.625657 0 -0 0</pose>
          <mass>250.2</mass>
          <inertia>
            <ixx>40.2192</ixx>
            <ixy>0</ixy>
            <ixz>2.39047</ixz>
            <iyy>51.7554</iyy>
            <iyz>0</iyz>
            <izz>31.9497</izz>
          </inertia>
        </inertial>
        <collision name='base_link_fixed_joint_lump__body_bottom_link_collision'>
          <pose frame=''>0 0 0.4786 0 -0 0</pose>
          <geometry>
            <box>
              <size>1.05 0.7 0.5</size>
            </box>
          </geometry>
          <surface>
            <contact>
              <ode/>
            </contact>
            <friction>
              <ode/>
              <torsional>
                <ode/>
              </torsional>
            </friction>
            <bounce/>
          </surface>
          <max_contacts>10</max_contacts>
        </collision>
        <collision name='base_link_fixed_joint_lump__velodyne_base_link_collision_1'>
          <pose frame=''>0.075 0 1.96445 0 -0 0</pose>
          <geometry>
            <cylinder>
              <length>0.0717</length>
              <radius>0.0516</radius>
            </cylinder>
          </geometry>
          <max_contacts>10</max_contacts>
          <surface>
            <contact>
              <ode/>
            </contact>
            <bounce/>
            <friction>
              <torsional>
                <ode/>
              </torsional>
              <ode/>
            </friction>
          </surface>
        </collision>
        <collision name='base_link_fixed_joint_lump__body_middle_link_collision_2'>
          <pose frame=''>-0.1 0 1.1786 0 -0 0</pose>
          <geometry>
            <box>
              <size>0.85 0.7 0.9</size>
            </box>
          </geometry>
          <surface>
            <contact>
              <ode/>
            </contact>
            <friction>
              <ode/>
              <torsional>
                <ode/>
              </torsional>
            </friction>
            <bounce/>
          </surface>
          <max_contacts>10</max_contacts>
        </collision>
        <collision name='base_link_fixed_joint_lump__body_top_link_collision_3'>
          <pose frame=''>0.075 0 1.7786 0 -0 0</pose>
          <geometry>
            <box>
              <size>0.05 0.05 0.3</size>
            </box>
          </geometry>
          <surface>
            <contact>
              <ode/>
            </contact>
            <friction>
              <ode/>
              <torsional>
                <ode/>
              </torsional>
            </friction>
            <bounce/>
          </surface>
          <max_contacts>10</max_contacts>
        </collision>
        <visual name='base_link_fixed_joint_lump__body_bottom_link_visual'>
          <pose frame=''>0 0 0.4786 0 -0 0</pose>
          <geometry>
            <box>
              <size>1.05 0.7 0.5</size>
            </box>
          </geometry>
          <material>
            <script>
              <name>Gazebo/Gray</name>
              <uri>file://media/materials/scripts/gazebo.material</uri>
            </script>
          </material>
        </visual>
        <visual name='base_link_fixed_joint_lump__velodyne_base_link_visual_1'>
          <pose frame=''>0.075 0 1.9286 0 -0 0</pose>
          <geometry>
            <mesh>
              <scale>1 1 1</scale>
              <uri>/root/catkin_ws/src/velodyne_simulator/velodyne_description/meshes/VLP16_base_1.dae</uri>
            </mesh>
          </geometry>
        </visual>
        <visual name='base_link_fixed_joint_lump__velodyne_base_link_visual_2'>
          <pose frame=''>0.075 0 1.9286 0 -0 0</pose>
          <geometry>
            <mesh>
              <scale>1 1 1</scale>
              <uri>/root/catkin_ws/src/velodyne_simulator/velodyne_description/meshes/VLP16_base_2.dae</uri>
            </mesh>
          </geometry>
        </visual>
        <visual name='base_link_fixed_joint_lump__velodyne_visual_3'>
          <pose frame=''>0.075 0 1.9286 0 -0 0</pose>
          <geometry>
            <mesh>
              <scale>1 1 1</scale>
              <uri>/root/catkin_ws/src/velodyne_simulator/velodyne_description/meshes/VLP16_scan.dae</uri>
            </mesh>
          </geometry>
          <material>
            <script>
              <uri>__default__</uri>
              <name>__default__</name>
            </script>
          </material>
        </visual>
        <visual name='base_link_fixed_joint_lump__body_middle_link_visual_4'>
          <pose frame=''>-0.1 0 1.1786 0 -0 0</pose>
          <geometry>
            <box>
              <size>0.85 0.7 0.9</size>
            </box>
          </geometry>
          <material>
            <script>
              <name>Gazebo/Gray</name>
              <uri>file://media/materials/scripts/gazebo.material</uri>
            </script>
          </material>
        </visual>
        <visual name='base_link_fixed_joint_lump__body_top_link_visual_5'>
          <pose frame=''>0.075 0 1.7786 0 -0 0</pose>
          <geometry>
            <box>
              <size>0.05 0.05 0.3</size>
            </box>
          </geometry>
          <material>
            <script>
              <name>Gazebo/Gray</name>
              <uri>file://media/materials/scripts/gazebo.material</uri>
            </script>
          </material>
        </visual>
        <velocity_decay/>
        <velocity_decay/>
        <sensor name='velodyne-VLP16' type='ray'>
          <visualize>0</visualize>
          <update_rate>10</update_rate>
          <ray>
            <scan>
              <horizontal>
                <samples>1875</samples>
                <resolution>1</resolution>
                <min_angle>-3.14159</min_angle>
                <max_angle>3.14159</max_angle>
              </horizontal>
              <vertical>
                <samples>16</samples>
                <resolution>1</resolution>
                <min_angle>-0.261799</min_angle>
                <max_angle>0.261799</max_angle>
              </vertical>
            </scan>
            <range>
              <min>0.055</min>
              <max>140</max>
              <resolution>0.001</resolution>
            </range>
            <noise>
              <type>gaussian</type>
              <mean>0</mean>
              <stddev>0</stddev>
            </noise>
          </ray>
          <plugin name='gazebo_ros_laser_controller' filename='libgazebo_ros_velodyne_laser.so'>
            <topicName>/velodyne_points</topicName>
            <frameName>velodyne</frameName>
            <min_range>0.9</min_range>
            <max_range>130.0</max_range>
            <gaussianNoise>0.008</gaussianNoise>
            <robotNamespace>/</robotNamespace>
          </plugin>
          <pose frame=''>0.075 0 1.9663 0 -0 0</pose>
        </sensor>
        <velocity_decay/>
        <gravity>1</gravity>
        <velocity_decay/>
        <self_collide>0</self_collide>
        <enable_wind>0</enable_wind>
        <kinematic>0</kinematic>
      </link>
      <link name='ackermann_front_steer'>
        <pose frame=''>0.525 0 0.2286 0 -0 0</pose>
        <inertial>
          <pose frame=''>0 0 0.3 0 -0 0</pose>
          <mass>0.2</mass>
          <inertia>
            <ixx>0.000541667</ixx>
            <ixy>0</ixy>
            <ixz>0</ixz>
            <iyy>0.000541667</iyy>
            <iyz>0</iyz>
            <izz>0.001</izz>
          </inertia>
        </inertial>
        <collision name='ackermann_front_steer_collision'>
          <pose frame=''>0 0 0.3 0 -0 0</pose>
          <geometry>
            <cylinder>
              <length>0.05</length>
              <radius>0.1</radius>
            </cylinder>
          </geometry>
          <surface>
            <contact>
              <ode/>
            </contact>
            <friction>
              <ode/>
              <torsional>
                <ode/>
              </torsional>
            </friction>
            <bounce/>
          </surface>
          <max_contacts>10</max_contacts>
        </collision>
        <gravity>1</gravity>
        <velocity_decay/>
        <self_collide>0</self_collide>
        <enable_wind>0</enable_wind>
        <kinematic>0</kinematic>
      </link>
      <joint name='ackermann_front_steer_hinge' type='revolute'>
        <child>ackermann_front_steer</child>
        <parent>base_link</parent>
        <axis>
          <xyz>0 0 1</xyz>
          <limit>
            <lower>-0.2</lower>
            <upper>0.2</upper>
            <effort>10</effort>
            <velocity>5</velocity>
          </limit>
          <dynamics>
            <damping>0.1</damping>
            <friction>0</friction>
            <spring_reference>0</spring_reference>
            <spring_stiffness>0</spring_stiffness>
          </dynamics>
          <use_parent_model_frame>1</use_parent_model_frame>
        </axis>
      </joint>
      <link name='ackermann_virtual_rear_wheel'>
        <pose frame=''>-0.525 0 0.2286 -1.5708 0 0</pose>
        <inertial>
          <pose frame=''>0 0 0 0 -0 0</pose>
          <mass>1</mass>
          <inertia>
            <ixx>0.000883601</ixx>
            <ixy>0</ixy>
            <ixz>0</ixz>
            <iyy>0.000883601</iyy>
            <iyz>0</iyz>
            <izz>0.00045</izz>
          </inertia>
        </inertial>
        <collision name='ackermann_virtual_rear_wheel_collision'>
          <pose frame=''>0 0 0 0 -0 0</pose>
          <geometry>
            <cylinder>
              <length>0.0889</length>
              <radius>0.03</radius>
            </cylinder>
          </geometry>
          <surface>
            <contact>
              <ode/>
            </contact>
            <friction>
              <ode/>
              <torsional>
                <ode/>
              </torsional>
            </friction>
            <bounce/>
          </surface>
          <max_contacts>10</max_contacts>
        </collision>
        <gravity>1</gravity>
        <velocity_decay/>
        <self_collide>0</self_collide>
        <enable_wind>0</enable_wind>
        <kinematic>0</kinematic>
      </link>
      <joint name='ackermann_virtual_rear_wheel_rotate' type='revolute'>
        <child>ackermann_virtual_rear_wheel</child>
        <parent>base_link</parent>
        <axis>
          <xyz>0 1 0</xyz>
          <limit>
            <lower>-1e+16</lower>
            <upper>1e+16</upper>
          </limit>
          <dynamics>
            <damping>0.1</damping>
            <friction>0</friction>
            <spring_reference>0</spring_reference>
            <spring_stiffness>0</spring_stiffness>
          </dynamics>
          <use_parent_model_frame>1</use_parent_model_frame>
        </axis>
      </joint>
      <link name='left_front_wheel_assembly'>
        <pose frame=''>0.525 0.4389 0.2286 0 -0 0</pose>
        <inertial>
          <pose frame=''>0 0 0.3 0 -0 0</pose>
          <mass>0.2</mass>
          <inertia>
            <ixx>0.000286667</ixx>
            <ixy>0</ixy>
            <ixz>0</ixz>
            <iyy>0.000286667</iyy>
            <iyz>0</iyz>
            <izz>0.00049</izz>
          </inertia>
        </inertial>
        <collision name='left_front_wheel_assembly_collision'>
          <pose frame=''>0 0 0.3 0 -0 0</pose>
          <geometry>
            <cylinder>
              <length>0.05</length>
              <radius>0.07</radius>
            </cylinder>
          </geometry>
          <surface>
            <contact>
              <ode/>
            </contact>
            <friction>
              <ode>
                <mu>inf</mu>
                <mu2>inf</mu2>
              </ode>
              <torsional>
                <ode/>
              </torsional>
            </friction>
            <bounce/>
          </surface>
          <max_contacts>10</max_contacts>
        </collision>
        <gravity>1</gravity>
        <velocity_decay/>
        <self_collide>0</self_collide>
        <enable_wind>0</enable_wind>
        <kinematic>0</kinematic>
      </link>
      <joint name='left_front_wheel_hinge' type='revolute'>
        <child>left_front_wheel_assembly</child>
        <parent>base_link</parent>
        <axis>
          <xyz>0 0 1</xyz>
          <limit>
            <lower>-0.2</lower>
            <upper>0.2</upper>
            <effort>10</effort>
            <velocity>0.1</velocity>
          </limit>
          <dynamics>
            <spring_reference>0</spring_reference>
            <spring_stiffness>0</spring_stiffness>
          </dynamics>
          <use_parent_model_frame>1</use_parent_model_frame>
        </axis>
      </joint>
      <link name='left_front_wheel'>
        <pose frame=''>0.525 0.4389 0.2286 -1.5708 0 0</pose>
        <inertial>
          <pose frame=''>0 0 0 0 -0 0</pose>
          <mass>0.5</mass>
          <inertia>
            <ixx>0.00686155</ixx>
            <ixy>0</ixy>
            <ixz>0</ixz>
            <iyy>0.00686155</iyy>
            <iyz>0</iyz>
            <izz>0.0130645</izz>
          </inertia>
        </inertial>
        <collision name='left_front_wheel_collision'>
          <pose frame=''>0 0 0 0 -0 0</pose>
          <geometry>
            <cylinder>
              <length>0.0889</length>
              <radius>0.2286</radius>
            </cylinder>
          </geometry>
          <surface>
            <contact>
              <ode/>
            </contact>
            <friction>
              <ode>
                <mu>inf</mu>
                <mu2>inf</mu2>
              </ode>
              <torsional>
                <ode/>
              </torsional>
            </friction>
            <bounce/>
          </surface>
          <max_contacts>10</max_contacts>
        </collision>
        <visual name='left_front_wheel_visual'>
          <pose frame=''>0 0 0 0 -0 0</pose>
          <geometry>
            <cylinder>
              <length>0.0889</length>
              <radius>0.2286</radius>
            </cylinder>
          </geometry>
          <material>
            <script>
              <name>Gazebo/Red</name>
              <uri>file://media/materials/scripts/gazebo.material</uri>
            </script>
          </material>
        </visual>
        <gravity>1</gravity>
        <velocity_decay/>
        <self_collide>0</self_collide>
        <enable_wind>0</enable_wind>
        <kinematic>0</kinematic>
      </link>
      <joint name='left_front_wheel_rotate' type='revolute'>
        <child>left_front_wheel</child>
        <parent>left_front_wheel_assembly</parent>
        <axis>
          <xyz>0 1 0</xyz>
          <limit>
            <lower>-1e+16</lower>
            <upper>1e+16</upper>
          </limit>
          <dynamics>
            <spring_reference>0</spring_reference>
            <spring_stiffness>0</spring_stiffness>
          </dynamics>
          <use_parent_model_frame>1</use_parent_model_frame>
        </axis>
      </joint>
      <link name='left_rear_wheel'>
        <pose frame=''>-0.525 0.4389 0.2286 -1.5708 0 0</pose>
        <inertial>
          <pose frame=''>0 0 0 0 -0 0</pose>
          <mass>0.5</mass>
          <inertia>
            <ixx>0.00686155</ixx>
            <ixy>0</ixy>
            <ixz>0</ixz>
            <iyy>0.00686155</iyy>
            <iyz>0</iyz>
            <izz>0.0130645</izz>
          </inertia>
        </inertial>
        <collision name='left_rear_wheel_collision'>
          <pose frame=''>0 0 0 0 -0 0</pose>
          <geometry>
            <cylinder>
              <length>0.0889</length>
              <radius>0.2286</radius>
            </cylinder>
          </geometry>
          <surface>
            <contact>
              <ode/>
            </contact>
            <friction>
              <ode>
                <mu>inf</mu>
                <mu2>inf</mu2>
              </ode>
              <torsional>
                <ode/>
              </torsional>
            </friction>
            <bounce/>
          </surface>
          <max_contacts>10</max_contacts>
        </collision>
        <visual name='left_rear_wheel_visual'>
          <pose frame=''>0 0 0 0 -0 0</pose>
          <geometry>
            <cylinder>
              <length>0.0889</length>
              <radius>0.2286</radius>
            </cylinder>
          </geometry>
          <material>
            <script>
              <name>Gazebo/Red</name>
              <uri>file://media/materials/scripts/gazebo.material</uri>
            </script>
          </material>
        </visual>
        <gravity>1</gravity>
        <velocity_decay/>
        <self_collide>0</self_collide>
        <enable_wind>0</enable_wind>
        <kinematic>0</kinematic>
      </link>
      <joint name='left_rear_wheel_rotate' type='revolute'>
        <child>left_rear_wheel</child>
        <parent>base_link</parent>
        <axis>
          <xyz>0 1 0</xyz>
          <limit>
            <lower>-1e+16</lower>
            <upper>1e+16</upper>
          </limit>
          <dynamics>
            <spring_reference>0</spring_reference>
            <spring_stiffness>0</spring_stiffness>
          </dynamics>
          <use_parent_model_frame>1</use_parent_model_frame>
        </axis>
      </joint>
      <link name='right_front_wheel_assembly'>
        <pose frame=''>0.525 -0.4389 0.2286 0 -0 0</pose>
        <inertial>
          <pose frame=''>0 0 0.3 0 -0 0</pose>
          <mass>0.2</mass>
          <inertia>
            <ixx>0.000286667</ixx>
            <ixy>0</ixy>
            <ixz>0</ixz>
            <iyy>0.000286667</iyy>
            <iyz>0</iyz>
            <izz>0.00049</izz>
          </inertia>
        </inertial>
        <collision name='right_front_wheel_assembly_collision'>
          <pose frame=''>0 0 0.3 0 -0 0</pose>
          <geometry>
            <cylinder>
              <length>0.05</length>
              <radius>0.07</radius>
            </cylinder>
          </geometry>
          <surface>
            <contact>
              <ode/>
            </contact>
            <friction>
              <ode>
                <mu>inf</mu>
                <mu2>inf</mu2>
              </ode>
              <torsional>
                <ode/>
              </torsional>
            </friction>
            <bounce/>
          </surface>
          <max_contacts>10</max_contacts>
        </collision>
        <gravity>1</gravity>
        <velocity_decay/>
        <self_collide>0</self_collide>
        <enable_wind>0</enable_wind>
        <kinematic>0</kinematic>
      </link>
      <joint name='right_front_wheel_hinge' type='revolute'>
        <child>right_front_wheel_assembly</child>
        <parent>base_link</parent>
        <axis>
          <xyz>0 0 1</xyz>
          <limit>
            <lower>-0.2</lower>
            <upper>0.2</upper>
            <effort>10</effort>
            <velocity>0.1</velocity>
          </limit>
          <dynamics>
            <spring_reference>0</spring_reference>
            <spring_stiffness>0</spring_stiffness>
          </dynamics>
          <use_parent_model_frame>1</use_parent_model_frame>
        </axis>
      </joint>
      <link name='right_front_wheel'>
        <pose frame=''>0.525 -0.4389 0.2286 -1.5708 0 0</pose>
        <inertial>
          <pose frame=''>0 0 0 0 -0 0</pose>
          <mass>0.5</mass>
          <inertia>
            <ixx>0.00686155</ixx>
            <ixy>0</ixy>
            <ixz>0</ixz>
            <iyy>0.00686155</iyy>
            <iyz>0</iyz>
            <izz>0.0130645</izz>
          </inertia>
        </inertial>
        <collision name='right_front_wheel_collision'>
          <pose frame=''>0 0 0 0 -0 0</pose>
          <geometry>
            <cylinder>
              <length>0.0889</length>
              <radius>0.2286</radius>
            </cylinder>
          </geometry>
          <surface>
            <contact>
              <ode/>
            </contact>
            <friction>
              <ode>
                <mu>inf</mu>
                <mu2>inf</mu2>
              </ode>
              <torsional>
                <ode/>
              </torsional>
            </friction>
            <bounce/>
          </surface>
          <max_contacts>10</max_contacts>
        </collision>
        <visual name='right_front_wheel_visual'>
          <pose frame=''>0 0 0 0 -0 0</pose>
          <geometry>
            <cylinder>
              <length>0.0889</length>
              <radius>0.2286</radius>
            </cylinder>
          </geometry>
          <material>
            <script>
              <name>Gazebo/Red</name>
              <uri>file://media/materials/scripts/gazebo.material</uri>
            </script>
          </material>
        </visual>
        <gravity>1</gravity>
        <velocity_decay/>
        <self_collide>0</self_collide>
        <enable_wind>0</enable_wind>
        <kinematic>0</kinematic>
      </link>
      <joint name='right_front_wheel_rotate' type='revolute'>
        <child>right_front_wheel</child>
        <parent>right_front_wheel_assembly</parent>
        <axis>
          <xyz>0 1 0</xyz>
          <limit>
            <lower>-1e+16</lower>
            <upper>1e+16</upper>
          </limit>
          <dynamics>
            <spring_reference>0</spring_reference>
            <spring_stiffness>0</spring_stiffness>
          </dynamics>
          <use_parent_model_frame>1</use_parent_model_frame>
        </axis>
      </joint>
      <link name='right_rear_wheel'>
        <pose frame=''>-0.525 -0.4389 0.2286 -1.5708 0 0</pose>
        <inertial>
          <pose frame=''>0 0 0 0 -0 0</pose>
          <mass>0.5</mass>
          <inertia>
            <ixx>0.00686155</ixx>
            <ixy>0</ixy>
            <ixz>0</ixz>
            <iyy>0.00686155</iyy>
            <iyz>0</iyz>
            <izz>0.0130645</izz>
          </inertia>
        </inertial>
        <collision name='right_rear_wheel_collision'>
          <pose frame=''>0 0 0 0 -0 0</pose>
          <geometry>
            <cylinder>
              <length>0.0889</length>
              <radius>0.2286</radius>
            </cylinder>
          </geometry>
          <surface>
            <contact>
              <ode/>
            </contact>
            <friction>
              <ode>
                <mu>inf</mu>
                <mu2>inf</mu2>
              </ode>
              <torsional>
                <ode/>
              </torsional>
            </friction>
            <bounce/>
          </surface>
          <max_contacts>10</max_contacts>
        </collision>
        <visual name='right_rear_wheel_visual'>
          <pose frame=''>0 0 0 0 -0 0</pose>
          <geometry>
            <cylinder>
              <length>0.0889</length>
              <radius>0.2286</radius>
            </cylinder>
          </geometry>
          <material>
            <script>
              <name>Gazebo/Red</name>
              <uri>file://media/materials/scripts/gazebo.material</uri>
            </script>
          </material>
        </visual>
        <gravity>1</gravity>
        <velocity_decay/>
        <self_collide>0</self_collide>
        <enable_wind>0</enable_wind>
        <kinematic>0</kinematic>
      </link>
      <joint name='right_rear_wheel_rotate' type='revolute'>
        <child>right_rear_wheel</child>
        <parent>base_link</parent>
        <axis>
          <xyz>0 1 0</xyz>
          <limit>
            <lower>-1e+16</lower>
            <upper>1e+16</upper>
          </limit>
          <dynamics>
            <spring_reference>0</spring_reference>
            <spring_stiffness>0</spring_stiffness>
          </dynamics>
          <use_parent_model_frame>1</use_parent_model_frame>
        </axis>
      </joint>
      <static>0</static>
      <plugin name='gazebo_ros_control' filename='libgazebo_ros_control.so'>
        <robotNamespace>/</robotNamespace>
        <robotSimType>steer_bot_hardware_gazebo/SteerBotHardwareGazebo</robotSimType>
        <legacyModeNS>1</legacyModeNS>
      </plugin>
      <pose frame=''>0 0 0.2 0 -0 0</pose>
    </model>
  </world>
</sdf>
