<?xml version="1.0"?>
<robot xmlns:xacro="http://www.ros.org/wiki/xacro" name="soma">

    <!-- Front wheel macro -->
	<macro name="front_wheel_macro" params="parent prefix xyz">
		
		<!-- General properties used for inertia computation -->
		<property name="mass" value="0.5" />
		<property name="radius" value="0.2" />
		<property name="length" value="0.1" />

		<!-- Joints -->
        <joint name="${prefix}_front_wheel_hinge" type="revolute"> 
            <parent link="${parent}"/> 
            <child link="${prefix}_front_wheel_assembly"/> 
            <origin xyz="${xyz}" rpy="0 0 0" />  
            <axis xyz="0 0 1" rpy="0 0 0" />
            <limit effort="100" velocity="1" lower="-1" upper="1"/> 
            <dynamics damping="0.0" friction="0.0"/> 
        </joint> 

        <joint name="${prefix}_front_wheel_rotate" type="continuous"> 
            <parent link="${prefix}_front_wheel_assembly"/> 
            <child link="${prefix}_front_wheel"/> 
            <origin xyz="0.0 0.0 0.0" rpy="0 0 0" />  
            <axis xyz="0 1 0" rpy="0 0 0" /> 
            <limit effort="100" velocity="50"/> 
            <dynamics damping="0.0" friction="0.0"/> 
        </joint>

		<!-- Transmissions -->
        <transmission name="${prefix}_front_wheel_hinge_trans">
            <type>transmission_interface/SimpleTransmission</type>
            <joint name="${prefix}_front_wheel_hinge">
                <hardwareInterface>EffortJointInterface</hardwareInterface>
            </joint>
            <actuator name="${prefix}_front_wheel_hinge_motor">
                <hardwareInterface>EffortJointInterface</hardwareInterface>
                <mechanicalReduction>1</mechanicalReduction>
            </actuator>
        </transmission>

        <transmission name="${prefix}_front_wheel_rotate_trans">
            <type>transmission_interface/SimpleTransmission</type>
            <joint name="${prefix}_front_wheel_rotate">
                <hardwareInterface>EffortJointInterface</hardwareInterface>
            </joint>
            <actuator name="${prefix}_front_wheel_rotate_motor">
                <hardwareInterface>EffortJointInterface</hardwareInterface>
                <mechanicalReduction>1</mechanicalReduction>
            </actuator>
        </transmission>

		<!-- Links -->
        <link name="${prefix}_front_wheel"> 
            
            <!-- Collision part -->
            <collision> 
                <origin xyz="0 0 0" rpy="0 ${pi/2} ${pi/2}" />
                <geometry> 
                    <cylinder length="${length}" radius="${radius}"/> 
                </geometry> 
            </collision> 

            <!-- Visual part -->
            <visual> 
                <origin xyz="0 0 0" rpy="0 ${pi/2} ${pi/2}" /> 
                <geometry> 
                    <cylinder length="${length}" radius="${radius}"/> 
                </geometry> 
                <material name="black"/> 
            </visual> 		

            <!-- Inertial part -->
            <inertial> 
                <origin xyz="0 0 0" rpy="0 ${pi/2} ${pi/2}" /> 
                <mass value="${mass}"/> 
                <cylinder_inertia mass="${mass}" radius="${radius}" height="${length}" />  
            </inertial> 

        </link>

        <link name="${prefix}_front_wheel_assembly">

            <!-- Collision part -->
            <collision> 
                <origin xyz="0 0 0" rpy="0 ${pi/2} ${pi/2}" />
                <geometry> 
                    <cylinder length="0.001" radius="0.04"/> 
                </geometry> 
            </collision> 

            <!-- Visual part -->
            <visual> 
                <origin xyz="0 0 0" rpy="0 ${pi/2} ${pi/2}" /> 
                <geometry> 
                    <cylinder length="0.001" radius="0.04"/> 
                </geometry> 
                <material name="white"/> 
            </visual> 		

            <!-- Inertial part -->
            <inertial> 
                <origin xyz="0 0 0" rpy="0 ${pi/2} ${pi/2}" /> 
                <mass value="0.2"/> 
                <cylinder_inertia mass="0.2" radius="0.3" height="0.1"/> 
            </inertial>
        </link>  

		<!-- Gazebo additional parameters -->
		<gazebo reference="${prefix}_front_wheel">
			<material>
				Gazebo/Red
			</material>
			<mu1 value="2.5" />
			<mu2 value="2.5" />
			<kp value="50000" />
			<kd value="10" />
		</gazebo>

        <gazebo reference="${prefix}_front_wheel_assembly">
			<material>
				Gazebo/Red
			</material>
			<mu1 value="2.5" />
			<mu2 value="2.5" />
			<kp value="50000" />
			<kd value="10" />
		</gazebo>

	</macro>
	<!-- END front wheel macro -->

</robot> 