<?xml version="1.0"?>
<robot xmlns:xacro="http://www.ros.org/wiki/xacro" name="soma">

    <!-- Rear wheel macro -->
    <macro name="rear_wheel_macro" params="parent prefix xyz">

        <!-- General properties used for inertia computation -->
        <property name="mass" value="0.5" />
        <property name="radius" value="0.2286" />
        <property name="length" value="0.0889" />

        <!-- Joint -->
        <joint name="${prefix}_rear_wheel_rotate" type="continuous">
            <parent link="${parent}"/>
            <child link="${prefix}_rear_wheel"/>
            <origin xyz="${xyz}" rpy="${-pi/2} 0 0" />
            <axis xyz="0 0 1" rpy="0 0 0" />
            <limit effort="10" velocity="5"/>
            <!-- <dynamics damping="0.1"/> -->
        </joint>

        <!-- Transmission -->
        <transmission name="${prefix}_rear_wheel_rotate_trans">
            <type>transmission_interface/SimpleTransmission</type>
            <joint name="${prefix}_rear_wheel_rotate">
                <hardwareInterface>hardware_interface/VelocityJointInterface</hardwareInterface>
            </joint>
            <actuator name="${prefix}_rear_wheel_rotate_motor">
                <hardwareInterface>hardware_interface/VelocityJointInterface</hardwareInterface>
                <mechanicalReduction>1</mechanicalReduction>
            </actuator>
        </transmission>

        <!-- Link -->
        <link name="${prefix}_rear_wheel">

            <!-- Collision part -->
            <collision>
                <origin xyz="0 0 0" rpy="0 0 0" />
                <geometry>
                    <cylinder length="${length}" radius="${radius}"/>
                </geometry>
            </collision>

            <!-- Visual part -->
            <visual>
                <origin xyz="0 0 0" rpy="0 0 0" />
                <geometry>
                    <cylinder length="${length}" radius="${radius}"/>
                </geometry>
                <material name="black"/>
            </visual>

            <!-- Inertial part -->
            <inertial>
                <origin xyz="0 0 0" rpy="0 0 0" />
                <mass value="${mass}"/>
                <cylinder_inertia mass="${mass}" radius="${radius}" height="${length}" />
            </inertial>

        </link>

        <!-- Gazebo additional parameters -->
        <gazebo reference="${prefix}_rear_wheel">
            <material>
				Gazebo/Red
            </material>
            <mu1 value="Inf" />
            <mu2 value="Inf" />
            <!-- <kp value="1000000000" />
            <kd value="10" /> -->
        </gazebo>

    </macro>
    <!-- END rear wheel macro -->

</robot> 